<?xml version="1.0" ?>
<!-- =================================================================================== -->
<!-- | This document was autogenerated by xacro from /root/ros2_ws/src/ai_sapiens/ai_sapiens_description/urdf/k1_rev1/k1.urdf.xacro | -->
<!-- |    EDITING THIS FILE BY HAND IS NOT RECOMMENDED                                 | -->
<!-- =================================================================================== -->
<robot name="k1">
  <material name="dark">
    <color rgba="0.2 0.2 0.2 1"/>
  </material>
  <material name="white">
    <color rgba="0.7 0.7 0.7 1"/>
  </material>
  <material name="blue">
    <color rgba="0.0 0.0 1.0 1"/>
  </material>
  <mujoco>
    <compiler discardvisual="false" meshdir="package://ai_sapiens_description/meshes/k1_rev1"/>
  </mujoco>
  <link name="head_link">
    <visual>
      <origin rpy="0 0 0" xyz="0 0 0"/>
      <geometry>
        <mesh filename="package://ai_sapiens_description/meshes/k1_rev1/head_link.stl" scale="0.001 0.001 0.001"/>
      </geometry>
      <material name="white"/>
    </visual>
    <collision>
      <origin rpy="0 0 0" xyz="0 0 0"/>
      <geometry>
        <mesh filename="package://ai_sapiens_description/meshes/k1_rev1/head_link.stl" scale="0.001 0.001 0.001"/>
      </geometry>
    </collision>
    <inertial>
      <origin xyz="2.990236300e-02 -4.729033400e-04 7.998201000e-02"/>
      <mass value="5.502976800e-01"/>
      <inertia ixx="2.173484900e-03" ixy="3.966642100e-06" ixz="-4.271481800e-04" iyy="1.902348300e-03" iyz="7.214693700e-06" izz="1.574879600e-03"/>
    </inertial>
  </link>
  <link name="pelvis">
    <visual>
      <origin rpy="0 0 0" xyz="0 0 0"/>
      <geometry>
        <mesh filename="package://ai_sapiens_description/meshes/k1_rev1/pelvis.stl" scale="0.001 0.001 0.001"/>
      </geometry>
      <material name="white"/>
    </visual>
    <!-- <collision>
      <origin rpy="0 0 0" xyz="0 0 0"/>
      <geometry>
        <mesh filename="package://ai_sapiens_description/meshes/k1_rev1/pelvis.stl" scale="0.001 0.001 0.001"/>
      </geometry>
    </collision> -->
    <inertial>
      <origin xyz="-2.926489100e-03 1.127755300e-06 -5.031535600e-02"/>
      <mass value="3.611882200e+00"/>
      <inertia ixx="1.310639100e-02" ixy="-2.328809400e-07" ixz="5.514559000e-05" iyy="9.174952600e-03" iyz="0.000000000e+00" izz="7.736608000e-03"/>
    </inertial>
  </link>
  <!-- Legs -->
  <link name="left_hip_pitch_link">
    <visual>
      <origin rpy="0 0 0" xyz="0 0 0"/>
      <geometry>
        <mesh filename="package://ai_sapiens_description/meshes/k1_rev1/left_hip_pitch_link.stl" scale="0.001 0.001 0.001"/>
      </geometry>
      <material name="white"/>
    </visual>
    <collision>
      <origin rpy="1.5708 0 0" xyz="0 0.05 -0.02"/>
      <geometry>
        <cylinder length="0.07" radius="0.04"/>
      </geometry>
    </collision>
    <inertial>
      <origin xyz="-1.141670400e-03 7.948432600e-02 -2.579805100e-02"/>
      <mass value="1.134347800e+00"/>
      <inertia ixx="1.413286200e-03" ixy="1.518924500e-05" ixz="-1.201272000e-05" iyy="1.011148100e-03" iyz="1.525829600e-04" izz="1.066244600e-03"/>
    </inertial>
  </link>
  <joint name="left_hip_pitch_joint" type="revolute">
    <origin rpy="0 0 0" xyz="0.0 0.040 -0.081"/>
    <parent link="pelvis"/>
    <child link="left_hip_pitch_link"/>
    <axis xyz="0 1 0"/>
    <limit effort="96.9" lower="-2.4435" upper="2.4435" velocity="11.5"/>
  </joint>
  <link name="left_hip_roll_link">
    <visual>
      <origin rpy="0 0 0" xyz="0 0 0"/>
      <geometry>
        <mesh filename="package://ai_sapiens_description/meshes/k1_rev1/left_hip_roll_link.stl" scale="0.001 0.001 0.001"/>
      </geometry>
      <material name="white"/>
    </visual>
    <inertial>
      <origin xyz="1.451722900e-02 -2.959881100e-06 -7.908222600e-02"/>
      <mass value="1.553530600e+00"/>
      <inertia ixx="2.895595600e-03" ixy="2.404258600e-07" ixz="-7.419442800e-05" iyy="3.373316500e-03" iyz="-2.099420700e-07" izz="1.930198000e-03"/>
    </inertial>
  </link>
  <joint name="left_hip_roll_joint" type="revolute">
    <origin rpy="0 0 0" xyz="-0.008 0.085 -0.030"/>
    <parent link="left_hip_pitch_link"/>
    <child link="left_hip_roll_link"/>
    <axis xyz="1 0 0"/>
    <limit effort="96.9" lower="-0.6109" upper="2.5307" velocity="11.5"/>
  </joint>
  <link name="left_hip_yaw_link">
    <visual>
      <origin rpy="0 0 0" xyz="0 0 0"/>
      <geometry>
        <mesh filename="package://ai_sapiens_description/meshes/k1_rev1/left_hip_yaw_link.stl" scale="0.001 0.001 0.001"/>
      </geometry>
      <material name="white"/>
    </visual>
    <collision>
      <origin rpy="0 0 0" xyz="0.0 0 -0.08"/>
      <geometry>
        <cylinder length="0.13" radius="0.045"/>
      </geometry>
    </collision>
    <inertial>
      <origin xyz="-1.981771700e-03 -4.936338800e-03 -1.811417900e-01"/>
      <mass value="1.898213600e+00"/>
      <inertia ixx="1.106385300e-02" ixy="-5.976117400e-05" ixz="-4.863131900e-04" iyy="1.147674900e-02" iyz="-6.115589000e-04" izz="1.632573000e-03"/>
    </inertial>
  </link>
  <joint name="left_hip_yaw_joint" type="revolute">
    <origin rpy="0 0 0" xyz="0.015 0.0 -0.0905"/>
    <parent link="left_hip_roll_link"/>
    <child link="left_hip_yaw_link"/>
    <axis xyz="0 0 1"/>
    <limit effort="96.9" lower="-3.1416" upper="3.1416" velocity="11.5"/>
  </joint>
  <link name="left_knee_link">
    <visual>
      <origin rpy="0 0 0" xyz="0 0 0"/>
      <geometry>
        <mesh filename="package://ai_sapiens_description/meshes/k1_rev1/left_knee_link.stl" scale="0.001 0.001 0.001"/>
      </geometry>
      <material name="white"/>
    </visual>
    <inertial>
      <origin xyz="-3.870294200e-04 3.148109200e-03 -1.238798000e-01"/>
      <mass value="2.340311200e+00"/>
      <inertia ixx="1.081088800e-02" ixy="1.641625300e-04" ixz="-2.747466700e-04" iyy="1.105245000e-02" iyz="-3.835456300e-04" izz="2.561741000e-03"/>
    </inertial>
    <collision>
      <origin rpy="0 0 0" xyz="0.0 0 -0.10"/>
      <geometry>
        <cylinder length="0.18" radius="0.04"/>
      </geometry>
    </collision>
  </link>
  <joint name="left_knee_joint" type="revolute">
    <origin rpy="0 0 0" xyz="-0.007 0.0 -0.2365"/>
    <parent link="left_hip_yaw_link"/>
    <child link="left_knee_link"/>
    <axis xyz="0 1 0"/>
    <limit effort="96.9" lower="0" upper="2.3562" velocity="11.5"/>
  </joint>
  <link name="left_ankle_pitch_link">
    <visual>
      <origin rpy="0 0 0" xyz="0 0 0"/>
      <geometry>
        <mesh filename="package://ai_sapiens_description/meshes/k1_rev1/left_ankle_pitch_link.stl" scale="0.001 0.001 0.001"/>
      </geometry>
      <material name="white"/>
    </visual>
    <!--<collision>
      <origin rpy="0 0 0" xyz="0 0 0"/>
      <geometry>
        <mesh filename="package://ai_sapiens_description/meshes/k1_rev1/left_ankle_pitch_link.stl" scale="0.001 0.001 0.001"/>
      </geometry>
    </collision>-->
    <inertial>
      <origin xyz="5.032473200e-03 -3.766079000e-05 2.402319500e-03"/>
      <mass value="6.779372600e-01"/>
      <inertia ixx="3.704684500e-04" ixy="-1.179149700e-06" ixz="4.766622000e-05" iyy="4.135993600e-04" iyz="5.727227700e-07" izz="4.302869000e-04"/>
    </inertial>
  </link>
  <joint name="left_ankle_pitch_joint" type="revolute">
    <origin rpy="0 0 0" xyz="0.0 0.0 -0.294"/>
    <parent link="left_knee_link"/>
    <child link="left_ankle_pitch_link"/>
    <axis xyz="0 1 0"/>
    <limit effort="96.9" lower="-0.7854" upper="0.7854" velocity="11.5"/>
  </joint>
  <link name="left_ankle_roll_link">
    <visual>
      <origin rpy="0 0 0" xyz="0 0 0"/>
      <geometry>
        <mesh filename="package://ai_sapiens_description/meshes/k1_rev1/left_ankle_roll_link.stl" scale="0.001 0.001 0.001"/>
      </geometry>
      <material name="white"/>
    </visual>
    <collision>
      <origin rpy="0 0 0" xyz="0 0 0"/>
      <geometry>
        <mesh filename="package://ai_sapiens_description/meshes/k1_rev1/left_ankle_roll_link.stl" scale="0.001 0.001 0.001"/>
      </geometry>
    </collision>
    <inertial>
      <origin xyz="3.460414800e-02 4.987565000e-06 -4.095111700e-02"/>
      <mass value="6.616435000e-01"/>
      <inertia ixx="4.316320200e-04" ixy="8.340871900e-08" ixz="4.556600800e-05" iyy="1.641839900e-03" iyz="-3.054166700e-08" izz="1.722959300e-03"/>
    </inertial>
  </link>
  <joint name="left_ankle_roll_joint" type="revolute">
    <origin rpy="0 0 0" xyz="0 0 0.0"/>
    <parent link="left_ankle_pitch_link"/>
    <child link="left_ankle_roll_link"/>
    <axis xyz="1 0 0"/>
    <limit effort="47.3" lower="-0.5236" upper="0.5236" velocity="20.9"/>
  </joint>
  <link name="right_hip_pitch_link">
    <visual>
      <origin rpy="0 0 0" xyz="0 0 0"/>
      <geometry>
        <mesh filename="package://ai_sapiens_description/meshes/k1_rev1/right_hip_pitch_link.stl" scale="0.001 0.001 0.001"/>
      </geometry>
      <material name="white"/>
    </visual>
    <collision>
      <origin rpy="1.5708 0 0" xyz="0 -0.05 -0.02"/>
      <geometry>
        <cylinder length="0.07" radius="0.04"/>
      </geometry>
    </collision>
    <inertial>
      <origin xyz="-1.141350800e-03 -7.948863700e-02 -2.579253000e-02"/>
      <mass value="1.134347800e+00"/>
      <inertia ixx="1.413427800e-03" ixy="-1.539744300e-05" ixz="-1.209053000e-05" iyy="1.011315000e-03" iyz="-1.526223400e-04" izz="1.066188000e-03"/>
    </inertial>
  </link>
  <joint name="right_hip_pitch_joint" type="revolute">
    <origin rpy="0 0 0" xyz="0.0 -0.040 -0.081"/>
    <parent link="pelvis"/>
    <child link="right_hip_pitch_link"/>
    <axis xyz="0 1 0"/>
    <limit effort="96.9" lower="-2.4435" upper="2.4435" velocity="11.5"/>
  </joint>
  <link name="right_hip_roll_link">
    <visual>
      <origin rpy="0 0 0" xyz="0 0 0"/>
      <geometry>
        <mesh filename="package://ai_sapiens_description/meshes/k1_rev1/right_hip_roll_link.stl" scale="0.001 0.001 0.001"/>
      </geometry>
      <material name="white"/>
    </visual>
    <inertial>
      <origin xyz="1.451722900e-02 -2.959881100e-06 -7.908222600e-02"/>
      <mass value="1.553530600e+00"/>
      <inertia ixx="2.895595600e-03" ixy="2.404258600e-07" ixz="-7.419442800e-05" iyy="3.373592400e-03" iyz="2.679668900e-07" izz="1.929922100e-03"/>
    </inertial>
  </link>
  <joint name="right_hip_roll_joint" type="revolute">
    <origin rpy="0 0 0" xyz="-0.008 -0.085 -0.030"/>
    <parent link="right_hip_pitch_link"/>
    <child link="right_hip_roll_link"/>
    <axis xyz="1 0 0"/>
    <limit effort="96.9" lower="-2.5307" upper="0.6109" velocity="11.5"/>
  </joint>
  <link name="right_hip_yaw_link">
    <visual>
      <origin rpy="0 0 0" xyz="0 0 0"/>
      <geometry>
        <mesh filename="package://ai_sapiens_description/meshes/k1_rev1/right_hip_yaw_link.stl" scale="0.001 0.001 0.001"/>
      </geometry>
      <material name="white"/>
    </visual>
    <collision>
      <origin rpy="0 0 0" xyz="0.0 0 -0.08"/>
      <geometry>
        <cylinder length="0.13" radius="0.045"/>
      </geometry>
    </collision>
    <inertial>
      <origin xyz="-1.979799000e-03 4.937156100e-03 -1.811430100e-01"/>
      <mass value="1.898213600e+00"/>
      <inertia ixx="1.106355100e-02" ixy="6.007863900e-05" ixz="-4.880601900e-04" iyy="1.147669300e-02" iyz="6.113904800e-04" izz="1.632776900e-03"/>
    </inertial>
  </link>
  <joint name="right_hip_yaw_joint" type="revolute">
    <origin rpy="0 0 0" xyz="0.015 0.0 -0.0905"/>
    <parent link="right_hip_roll_link"/>
    <child link="right_hip_yaw_link"/>
    <axis xyz="0 0 1"/>
    <limit effort="96.9" lower="-3.1416" upper="3.1416" velocity="11.5"/>
  </joint>
  <link name="right_knee_link">
    <visual>
      <origin rpy="0 0 0" xyz="0 0 0"/>
      <geometry>
        <mesh filename="package://ai_sapiens_description/meshes/k1_rev1/right_knee_link.stl" scale="0.001 0.001 0.001"/>
      </geometry>
      <material name="white"/>
    </visual>
    <collision>
      <origin rpy="0 0 0" xyz="0.0 0 -0.10"/>
      <geometry>
        <cylinder length="0.18" radius="0.04"/>
      </geometry>
    </collision>
    <inertial>
      <origin xyz="-3.870294200e-04 -3.148109200e-03 -1.238798000e-01"/>
      <mass value="2.340311200e+00"/>
      <inertia ixx="1.081088800e-02" ixy="-1.641625300e-04" ixz="-2.747466700e-04" iyy="1.105245000e-02" iyz="3.835456300e-04" izz="2.561741000e-03"/>
    </inertial>
  </link>
  <joint name="right_knee_joint" type="revolute">
    <origin rpy="0 0 0" xyz="-0.007 0.0 -0.2365"/>
    <parent link="right_hip_yaw_link"/>
    <child link="right_knee_link"/>
    <axis xyz="0 1 0"/>
    <limit effort="96.9" lower="0" upper="2.3562" velocity="11.5"/>
  </joint>
  <link name="right_ankle_pitch_link">
    <visual>
      <origin rpy="0 0 0" xyz="0 0 0"/>
      <geometry>
        <mesh filename="package://ai_sapiens_description/meshes/k1_rev1/right_ankle_pitch_link.stl" scale="0.001 0.001 0.001"/>
      </geometry>
      <material name="white"/>
    </visual>
    <!--<collision>
      <origin rpy="0 0 0" xyz="0 0 0"/>
      <geometry>
        <mesh filename="package://ai_sapiens_description/meshes/k1_rev1/right_ankle_pitch_link.stl" scale="0.001 0.001 0.001"/>
      </geometry>
    </collision>-->
    <inertial>
      <origin xyz="5.032473200e-03 -3.766079000e-05 2.402319500e-03"/>
      <mass value="6.779372600e-01"/>
      <inertia ixx="3.704684500e-04" ixy="-1.179149700e-06" ixz="4.766622000e-05" iyy="4.135993600e-04" iyz="5.727227700e-07" izz="4.302869000e-04"/>
    </inertial>
  </link>
  <joint name="right_ankle_pitch_joint" type="revolute">
    <origin rpy="0 0 0" xyz="0.0 0.0 -0.294"/>
    <parent link="right_knee_link"/>
    <child link="right_ankle_pitch_link"/>
    <axis xyz="0 1 0"/>
    <limit effort="96.9" lower="-0.7854" upper="0.7854" velocity="11.5"/>
  </joint>
  <link name="right_ankle_roll_link">
    <visual>
      <origin rpy="0 0 0" xyz="0 0 0"/>
      <geometry>
        <mesh filename="package://ai_sapiens_description/meshes/k1_rev1/right_ankle_roll_link.stl" scale="0.001 0.001 0.001"/>
      </geometry>
      <material name="white"/>
    </visual>
    <collision>
      <origin rpy="0 0 0" xyz="0 0 0"/>
      <geometry>
        <mesh filename="package://ai_sapiens_description/meshes/k1_rev1/right_ankle_roll_link.stl" scale="0.001 0.001 0.001"/>
      </geometry>
    </collision>
    <inertial>
      <origin xyz="3.460414800e-02 4.987565000e-06 -4.095111700e-02"/>
      <mass value="6.616435000e-01"/>
      <inertia ixx="4.316320200e-04" ixy="8.340871900e-08" ixz="4.556600800e-05" iyy="1.641839900e-03" iyz="-3.054166700e-08" izz="1.722959300e-03"/>
    </inertial>
  </link>
  <joint name="right_ankle_roll_joint" type="revolute">
    <origin rpy="0 0 0" xyz="0 0 0.0"/>
    <parent link="right_ankle_pitch_link"/>
    <child link="right_ankle_roll_link"/>
    <axis xyz="1 0 0"/>
    <limit effort="47.3" lower="-0.5236" upper="0.5236" velocity="20.9"/>
  </joint>
  <joint name="waist_yaw_joint" type="revolute">
    <origin rpy="0 0 0" xyz="0 0 0"/>
    <parent link="pelvis"/>
    <child link="torso_link"/>
    <axis xyz="0 0 1"/>
    <limit effort="96.9" lower="-6.2832" upper="6.2832" velocity="11.5"/>
  </joint>
  <link name="torso_link">
    <visual>
      <origin rpy="0 0 0" xyz="0 0 0"/>
      <geometry>
        <mesh filename="package://ai_sapiens_description/meshes/k1_rev1/torso_link.stl" scale="0.001 0.001 0.001"/>
      </geometry>
      <material name="white"/>
    </visual>
    <!-- <collision>
      <origin rpy="0 0 0" xyz="0 0 0"/>
      <geometry>
        <mesh filename="package://ai_sapiens_description/meshes/k1_rev1/torso_link.stl" scale="0.001 0.001 0.001"/>
      </geometry>
    </collision> -->
    <collision>
      <origin rpy="0 0 0" xyz="-0.02 0 0.24"/>
      <geometry>
        <box size="0.2 0.17 0.17"/>
      </geometry>
    </collision>
    <inertial>
      <origin xyz="-1.396563000e-02 6.013817200e-04 2.110737900e-01"/>
      <mass value="7.719359000e+00"/>
      <inertia ixx="7.007645300e-02" ixy="1.354042500e-04" ixz="8.048294700e-03" iyy="6.272163000e-02" iyz="5.070979500e-04" izz="3.873419500e-02"/>
    </inertial>
  </link>
  <joint name="head_joint" type="fixed">
    <origin rpy="0 0 0" xyz="-0.0185 0 0.385"/>
    <parent link="torso_link"/>
    <child link="head_link"/>
  </joint>
  <link name="left_shoulder_pitch_link">
    <visual>
      <origin rpy="0 0 0" xyz="0 0 0"/>
      <geometry>
        <mesh filename="package://ai_sapiens_description/meshes/k1_rev1/left_shoulder_pitch_link.stl" scale="0.001 0.001 0.001"/>
      </geometry>
      <material name="white"/>
    </visual>
    <collision>
      <origin rpy="0 1.5707963267948966 0" xyz="0 0.075 0.0"/>
      <geometry>
        <cylinder length="0.05" radius="0.032"/>
      </geometry>
    </collision>
    <inertial>
      <origin xyz="-2.860536300e-03 7.356480000e-02 4.028907400e-07"/>
      <mass value="6.074257400e-01"/>
      <inertia ixx="3.529038200e-04" ixy="6.203581100e-06" ixz="1.531761200e-07" iyy="3.006119200e-04" iyz="-6.976634300e-08" izz="3.483928700e-04"/>
    </inertial>
  </link>
  <joint name="left_shoulder_pitch_joint" type="revolute">
    <origin rpy="0 0 0" xyz="0.0015 0.069 0.319"/>
    <parent link="torso_link"/>
    <child link="left_shoulder_pitch_link"/>
    <axis xyz="0 1 0"/>
    <limit effort="47.3" lower="-3.1416" upper="3.1416" velocity="20.9"/>
  </joint>
  <link name="left_shoulder_roll_link">
    <visual>
      <origin rpy="0 0 0" xyz="0 0 0"/>
      <geometry>
        <mesh filename="package://ai_sapiens_description/meshes/k1_rev1/left_shoulder_roll_link.stl" scale="0.001 0.001 0.001"/>
      </geometry>
      <material name="white"/>
    </visual>
    <collision>
      <origin rpy="0 0 0" xyz="0.0 0.000 -0.13"/>
      <geometry>
        <cylinder length="0.08" radius="0.035"/>
      </geometry>
    </collision>
    <inertial>
      <origin xyz="-8.598869800e-04 -1.401330200e-06 -6.266809700e-02"/>
      <mass value="7.676193300e-01"/>
      <inertia ixx="7.540640300e-04" ixy="5.316734200e-08" ixz="-3.800846300e-05" iyy="9.381096300e-04" iyz="2.458188500e-08" izz="5.306054800e-04"/>
    </inertial>
  </link>
  <joint name="left_shoulder_roll_joint" type="revolute">
    <origin rpy="0 0 0" xyz="-0.005 0.077 0.0"/>
    <parent link="left_shoulder_pitch_link"/>
    <child link="left_shoulder_roll_link"/>
    <axis xyz="1 0 0"/>
    <limit effort="47.3" lower="0" upper="3.1416" velocity="20.9"/>
  </joint>
  <link name="left_shoulder_yaw_link">
    <visual>
      <origin rpy="0 0 0" xyz="0 0 0"/>
      <geometry>
        <mesh filename="package://ai_sapiens_description/meshes/k1_rev1/left_shoulder_yaw_link.stl" scale="0.001 0.001 0.001"/>
      </geometry>
      <material name="white"/>
    </visual>
    <inertial>
      <origin xyz="1.240965200e-02 -4.015957800e-03 -1.037212200e-01"/>
      <mass value="6.946265100e-01"/>
      <inertia ixx="7.202233300e-04" ixy="1.411072400e-05" ixz="1.081796000e-04" iyy="7.634050600e-04" iyz="-3.396234100e-05" izz="3.599643200e-04"/>
    </inertial>
  </link>
  <joint name="left_shoulder_yaw_joint" type="revolute">
    <origin rpy="0 0 0" xyz="0.0 0.0 -0.0687"/>
    <parent link="left_shoulder_roll_link"/>
    <child link="left_shoulder_yaw_link"/>
    <axis xyz="0 0 1"/>
    <limit effort="47.3" lower="-3.1416" upper="3.1416" velocity="20.9"/>
  </joint>
  <link name="left_elbow_link">
    <visual>
      <origin rpy="0 0 0" xyz="0 0 0"/>
      <geometry>
        <mesh filename="package://ai_sapiens_description/meshes/k1_rev1/left_elbow_link.stl" scale="0.001 0.001 0.001"/>
      </geometry>
      <material name="white"/>
    </visual>
    <inertial>
      <origin xyz="6.552039900e-02 4.121843400e-03 3.490233700e-06"/>
      <mass value="6.689549900e-01"/>
      <inertia ixx="3.736555000e-04" ixy="1.216866000e-04" ixz="5.296758300e-08" iyy="5.869930800e-04" iyz="-7.780705400e-08" izz="6.490868700e-04"/>
    </inertial>
  </link>
  <joint name="left_elbow_joint" type="revolute">
    <origin rpy="0 0 0" xyz="0.016 -0.007 -0.1153"/>
    <parent link="left_shoulder_yaw_link"/>
    <child link="left_elbow_link"/>
    <axis xyz="0 1 0"/>
    <limit effort="47.3" lower="-0.7854" upper="2.1817" velocity="20.9"/>
  </joint>
  <joint name="left_wrist_roll_joint" type="revolute">
    <origin rpy="0 0 0" xyz="0.0687 0.0 0.0"/>
    <axis xyz="1 0 0"/>
    <parent link="left_elbow_link"/>
    <child link="left_wrist_roll_rubber_hand"/>
    <limit effort="47.3" lower="-3.1416" upper="3.1416" velocity="20.9"/>
  </joint>
  <link name="left_wrist_roll_rubber_hand">
    <visual>
      <origin rpy="0 0 0" xyz="0 0 0"/>
      <geometry>
        <mesh filename="package://ai_sapiens_description/meshes/k1_rev1/left_wrist_roll_rubber_hand.stl" scale="0.001 0.001 0.001"/>
      </geometry>
      <material name="white"/>
    </visual>
    <collision>
      <origin rpy="0 0 0" xyz="0 0 0"/>
      <geometry>
        <mesh filename="package://ai_sapiens_description/meshes/k1_rev1/left_wrist_roll_rubber_hand.stl" scale="0.001 0.001 0.001"/>
      </geometry>
    </collision>
    <inertial>
      <origin xyz="1.407654200e-01 5.248631600e-04 4.039337300e-04"/>
      <mass value="3.690000000e-01"/>
      <inertia ixx="2.034216800e-04" ixy="1.009162400e-04" ixz="4.214169200e-05" iyy="2.413813900e-03" iyz="-3.970703900e-06" izz="2.355377400e-03"/>
    </inertial>
  </link>
  <link name="right_shoulder_pitch_link">
    <visual>
      <origin rpy="0 0 0" xyz="0 0 0"/>
      <geometry>
        <mesh filename="package://ai_sapiens_description/meshes/k1_rev1/right_shoulder_pitch_link.stl" scale="0.001 0.001 0.001"/>
      </geometry>
      <material name="white"/>
    </visual>
    <collision>
      <origin rpy="0 1.5707963267948966 0" xyz="0 -0.075 0.0"/>
      <geometry>
        <cylinder length="0.05" radius="0.032"/>
      </geometry>
    </collision>
    <inertial>
      <origin xyz="-2.860536300e-03 -7.356307300e-02 7.492072400e-06"/>
      <mass value="6.074257400e-01"/>
      <inertia ixx="3.528965800e-04" ixy="-6.237741300e-06" ixz="-2.831875200e-07" iyy="3.006118800e-04" iyz="-5.328462800e-08" izz="3.483856700e-04"/>
    </inertial>
  </link>
  <joint name="right_shoulder_pitch_joint" type="revolute">
    <origin rpy="0 0 0" xyz="0.0015 -0.069 0.319"/>
    <parent link="torso_link"/>
    <child link="right_shoulder_pitch_link"/>
    <axis xyz="0 1 0"/>
    <limit effort="47.3" lower="-3.1416" upper="3.1416" velocity="20.9"/>
  </joint>
  <link name="right_shoulder_roll_link">
    <visual>
      <origin rpy="0 0 0" xyz="0 0 0"/>
      <geometry>
        <mesh filename="package://ai_sapiens_description/meshes/k1_rev1/right_shoulder_roll_link.stl" scale="0.001 0.001 0.001"/>
      </geometry>
      <material name="white"/>
    </visual>
    <collision>
      <origin rpy="0 0 0" xyz="0.0 0.000 -0.13"/>
      <geometry>
        <cylinder length="0.08" radius="0.035"/>
      </geometry>
    </collision>
    <inertial>
      <origin xyz="-8.598870100e-04 -1.401330200e-06 -6.266809700e-02"/>
      <mass value="7.676193300e-01"/>
      <inertia ixx="7.540640300e-04" ixy="5.316741900e-08" ixz="-3.800846300e-05" iyy="9.381096300e-04" iyz="2.458187400e-08" izz="5.306054900e-04"/>
    </inertial>
  </link>
  <joint name="right_shoulder_roll_joint" type="revolute">
    <origin rpy="0 0 0" xyz="-0.005 -0.077 0.0"/>
    <parent link="right_shoulder_pitch_link"/>
    <child link="right_shoulder_roll_link"/>
    <axis xyz="1 0 0"/>
    <limit effort="47.3" lower="-3.1416" upper="0" velocity="20.9"/>
  </joint>
  <link name="right_shoulder_yaw_link">
    <visual>
      <origin rpy="0 0 0" xyz="0 0 0"/>
      <geometry>
        <mesh filename="package://ai_sapiens_description/meshes/k1_rev1/right_shoulder_yaw_link.stl" scale="0.001 0.001 0.001"/>
      </geometry>
      <material name="white"/>
    </visual>
    <inertial>
      <origin xyz="1.240965200e-02 4.015957800e-03 -1.037212200e-01"/>
      <mass value="6.946265100e-01"/>
      <inertia ixx="7.202233300e-04" ixy="-1.411072400e-05" ixz="1.081796000e-04" iyy="7.634050600e-04" iyz="3.396234100e-05" izz="3.599643200e-04"/>
    </inertial>
  </link>
  <joint name="right_shoulder_yaw_joint" type="revolute">
    <origin rpy="0 0 0" xyz="0.0 0.0 -0.0687"/>
    <parent link="right_shoulder_roll_link"/>
    <child link="right_shoulder_yaw_link"/>
    <axis xyz="0 0 1"/>
    <limit effort="47.3" lower="-3.1416" upper="3.1416" velocity="20.9"/>
  </joint>
  <link name="right_elbow_link">
    <visual>
      <origin rpy="0 0 0" xyz="0 0 0"/>
      <geometry>
        <mesh filename="package://ai_sapiens_description/meshes/k1_rev1/right_elbow_link.stl" scale="0.001 0.001 0.001"/>
      </geometry>
      <material name="white"/>
    </visual>
    <inertial>
      <origin xyz="6.552039900e-02 -4.121843900e-03 -3.490233700e-06"/>
      <mass value="6.689549900e-01"/>
      <inertia ixx="3.736555100e-04" ixy="-1.216866100e-04" ixz="-5.296758300e-08" iyy="5.869930800e-04" iyz="-7.780031300e-08" izz="6.490868900e-04"/>
    </inertial>
  </link>
  <joint name="right_elbow_joint" type="revolute">
    <origin rpy="0 0 0" xyz="0.016 0.007 -0.1153"/>
    <parent link="right_shoulder_yaw_link"/>
    <child link="right_elbow_link"/>
    <axis xyz="0 1 0"/>
    <limit effort="47.3" lower="-0.7854" upper="2.1817" velocity="20.9"/>
  </joint>
  <joint name="right_wrist_roll_joint" type="revolute">
    <origin rpy="0 0 0" xyz="0.0687 0.0 0.0"/>
    <axis xyz="1 0 0"/>
    <parent link="right_elbow_link"/>
    <child link="right_wrist_roll_rubber_hand"/>
    <limit effort="47.3" lower="-3.1416" upper="3.1416" velocity="20.9"/>
  </joint>
  <link name="right_wrist_roll_rubber_hand">
    <visual>
      <origin rpy="0 0 0" xyz="0 0 0"/>
      <geometry>
        <mesh filename="package://ai_sapiens_description/meshes/k1_rev1/right_wrist_roll_rubber_hand.stl" scale="0.001 0.001 0.001"/>
      </geometry>
      <material name="white"/>
    </visual>
    <collision>
      <origin rpy="0 0 0" xyz="0 0 0"/>
      <geometry>
        <mesh filename="package://ai_sapiens_description/meshes/k1_rev1/right_wrist_roll_rubber_hand.stl" scale="0.001 0.001 0.001"/>
      </geometry>
    </collision>
    <inertial>
      <origin xyz="1.407654300e-01 -5.248580800e-04 4.039340000e-04"/>
      <mass value="3.690000000e-01"/>
      <inertia ixx="2.034216600e-04" ixy="-1.009162000e-04" ixz="4.214169500e-05" iyy="2.413813900e-03" iyz="3.970701600e-06" izz="2.355377400e-03"/>
    </inertial>
  </link>
</robot>
